{"Subproblems": [{"Testcases": [{"status": 2, "Time": 15, "Memory": 9.3, "Input": "5\n7", "Answer": "210", "Output": "210\n", "Description": ""}, {"status": 2, "Time": 17, "Memory": 9.3, "Input": "10\n10", "Answer": "48620", "Output": "48620\n", "Description": ""}, {"status": 2, "Time": 15, "Memory": 9.3, "Input": "1\n1", "Answer": "1", "Output": "1\n", "Description": ""}, {"status": 6, "Time": 15, "Memory": 9.4, "Input": "15\n37", "Answer": "845649741", "Output": "937845656300\n", "Description": ""}, {"status": 2, "Time": 15, "Memory": 9.3, "Input": "1\n7", "Answer": "1", "Output": "1\n", "Description": ""}, {"status": 2, "Time": 16, "Memory": 9.2, "Input": "7\n2", "Answer": "7", "Output": "7\n", "Description": ""}, {"status": 2, "Time": 15, "Memory": 9.2, "Input": "4\n32", "Answer": "5984", "Output": "5984\n", "Description": ""}, {"status": 7, "Time": 0, "Memory": 0, "Input": "1000\n1000", "Answer": "965601742", "Output": "", "Description": "MemoryError\n\nDuring handling of the above exception, another exception occurred:\n\nTraceback (most recent call last):\n  File \"/P3\", line 9, in <module>\n    print(e(int(input()), int(input())))\nMemoryError\n"}], "Debugger": true, "Score": 50, "GetScore": 0}, {"Testcases": [{"status": 6, "Time": 20, "Memory": 9.4, "Input": "50\n50", "Answer": "267422234", "Output": "25477612258980856902730428600\n", "Description": ""}, {"status": 6, "Time": 19, "Memory": 9.3, "Input": "51\n28", "Answer": "823497870", "Output": "438387717763537500728\n", "Description": ""}, {"status": 6, "Time": 21, "Memory": 9.5, "Input": "93\n46", "Answer": "848374726", "Output": "3369079006958547823865906364534967200\n", "Description": ""}, {"status": 6, "Time": 16, "Memory": 9.3, "Input": "28\n23", "Answer": "896200283", "Output": "49699896548176\n", "Description": ""}], "Debugger": false, "Score": 50, "GetScore": 0}], "status": 11, "score": 0}